<?xml version="1.0" ?>
<robot name="IRB120">
  <material name="abb_orange"><color rgba="1.0 0.5 0.0 1.0"/></material>

  <material name="mat_steel"><color rgba="0.55 0.55 0.60 1.0"/></material>
  <material name="mat_blue"><color rgba="0.15 0.35 0.85 1.0"/></material>
  <material name="mat_green"><color rgba="0.00 0.70 0.25 1.0"/></material>
  <material name="mat_red"><color rgba="0.85 0.20 0.15 1.0"/></material>
  <material name="abb_dark_gray"><color rgba="0.02 0.02 0.02 1.0"/></material>
  <material name="collision_yellow"><color rgba="1.0 1.0 0.0 1.0"/></material>


    <link name="base_link">
        <inertial>
            <mass value="6.215" />
            <origin rpy="0 0 0" xyz="-0.04204 8.01E-05 0.07964" />
            <inertia ixx="0.0247272" ixy="-8.0784E-05" ixz="0.00130902" iyy="0.0491285" iyz="-8.0419E-06" izz="0.0472376" />
        </inertial>

        <visual>
            <origin rpy="0 0 0" xyz="0 0 0" />
            <geometry>
                <mesh filename="package://IRB120/urdf/meshes/visual/base_link.stl" />
            </geometry>
            <material name="abb_orange" />
        </visual>
        
        <collision>
            <origin rpy="0 0 0" xyz="0 0 0" />
            <geometry>
                <mesh filename="package://IRB120/urdf/meshes/collision/base_link.stl" />
            </geometry>
            <!-- <material name="collision_yellow" /> -->
        </collision>
    </link>
    <link name="link_1">
        
        <inertial>
            <mass value="3.067" />
            <origin rpy="0 0 0" xyz="9.77E-05 -0.00012 0.23841" />
            <inertia ixx="0.0142175" ixy="-1.28579E-05" ixz="-2.31364E-05" iyy="0.0144041" iyz="1.93404E-05" izz="0.0104533" />
        </inertial>

        <visual>
            <origin rpy="0 0 0" xyz="0 0 0" />
            <geometry>
                <mesh filename="package://IRB120/urdf/meshes/visual/link_1.stl" />
            </geometry>
            <material name="abb_orange" />
        </visual>
        <collision>
            <origin rpy="0 0 0" xyz="0 0 0" />
            <geometry>
                <mesh filename="package://IRB120/urdf/meshes/collision/link_1.stl" />
            </geometry>
            <!-- <material name="collision_yellow" /> -->
        </collision>
    </link>
    <link name="link_2">
        
        <inertial>
            <mass value="3.909" />
            <origin rpy="0 0 0" xyz="0.00078 -0.00212 0.10124" />
            <inertia ixx="0.0603111" ixy="9.83431E-06" ixz="5.72407E-05" iyy="0.041569" iyz="-0.00050497" izz="0.0259548" />
        </inertial>

        <visual>
            <origin rpy="0 0 0" xyz="0 0 0" />
            <geometry>
                <mesh filename="package://IRB120/urdf/meshes/visual/link_2.stl" />
            </geometry>
            <material name="abb_orange" />
        </visual>
        <collision>
            <origin rpy="0 0 0" xyz="0 0 0" />
            <geometry>
                <mesh filename="package://IRB120/urdf/meshes/collision/link_2.stl" />
            </geometry>
            <!-- <material name="collision_yellow" /> -->
        </collision>
    </link>
    <link name="link_3">
        
        <inertial>
            <mass value="2.944" />
            <origin rpy="0 0 0" xyz="0.02281 0.00106 0.05791" />
            <inertia ixx="0.00835606" ixy="-8.01545E-05" ixz="0.00142884" iyy="0.016713" iyz="-0.000182227" izz="0.0126984" />
        </inertial>

        <visual>
            <origin rpy="0 0 0" xyz="0 0 0" />
            <geometry>
                <mesh filename="package://IRB120/urdf/meshes/visual/link_3.stl" />
            </geometry>
            <material name="abb_orange" />
        </visual>
        <collision>
            <origin rpy="0 0 0" xyz="0 0 0" />
            <geometry>
                <mesh filename="package://IRB120/urdf/meshes/collision/link_3.stl" />
            </geometry>
            <!-- <material name="collision_yellow" /> -->
        </collision>
    </link>
    <link name="link_4">
        
        <inertial>
            <mass value="1.328" />
            <origin rpy="0 0 0" xyz="0.2247 0.00015 0.00041" />
            <inertia ixx="0.00284661" ixy="-2.12765E-05" ixz="-1.6435E-05" iyy="0.00401346" iyz="1.31336E-05" izz="0.0052535" />
        </inertial>

        <visual>
            <origin rpy="0 0 0" xyz="0 0 0" />
            <geometry>
                <mesh filename="package://IRB120/urdf/meshes/visual/link_4.stl" />
            </geometry>
            <material name="abb_orange" />
        </visual>
        <collision>
            <origin rpy="0 0 0" xyz="0 0 0" />
            <geometry>
                <mesh filename="package://IRB120/urdf/meshes/collision/link_4.stl" />
            </geometry>
            <!-- <material name="collision_yellow" /> -->
        </collision>
    </link>
    <link name="link_5">
        
        <inertial>
            <mass value="0.546" />
            <origin rpy="0 0 0" xyz="-0.00109 3.68E-05 6.22E-05" />
            <inertia ixx="0.000404891" ixy="1.61943E-06" ixz="8.46805E-07" iyy="0.000892825" iyz="-1.51792E-08" izz="0.000815468" />
        </inertial>

        <visual>
            <origin rpy="0 0 0" xyz="0 0 0" />
            <geometry>
                <mesh filename="package://IRB120/urdf/meshes/visual/link_5.stl" />
            </geometry>
            <material name="abb_orange" />
        </visual>
        <collision>
            <origin rpy="0 0 0" xyz="0 0 0" />
            <geometry>
                <mesh filename="package://IRB120/urdf/meshes/collision/link_5.stl" />
            </geometry>
            <!-- <material name="collision_yellow" /> -->
        </collision>
    </link>
    <link name="link_6">
        
        <inertial>
            <mass value="0.137" />
            <origin rpy="0 0 0" xyz="-0.00706 -0.00017 -1.32E-06" />
            <inertia ixx="0.001" ixy="0" ixz="0" iyy="0.001" iyz="0" izz="0.001" />
        </inertial>

        <visual>
            <origin rpy="0 0 0" xyz="0 0 0" />
            <geometry>
                <mesh filename="package://IRB120/urdf/meshes/visual/link_6.stl" />
            </geometry>
            <material name="abb_dark_gray" />
        </visual>
        <collision>
            <origin rpy="0 0 0" xyz="0 0 0" />
            <geometry>
                <mesh filename="package://IRB120/urdf/meshes/collision/link_6.stl" />
            </geometry>
            <!-- <material name="collision_yellow" /> -->
        </collision>
    </link>
    <link name="gripper_hand">
        <visual>
            <geometry>
                <mesh filename="package://IRB120/urdf/meshes/visual/hand.dae" />
            </geometry>
        </visual>
        <collision>
            <geometry>
                <mesh filename="package://IRB120/urdf/meshes/collision/hand.stl" />
            </geometry>
        </collision>
        
        <inertial>
            <mass value="0.1" />
            <inertia ixx="0.03" iyy="0.03" izz="0.03" ixy="0.0" ixz="0.0" iyz="0.0" />
        </inertial>

    </link>
    <link name="gripper_leftfinger">
        <visual>
            <geometry>
                <mesh filename="package://IRB120/urdf/meshes/visual/finger.dae" />
            </geometry>
        </visual>
        <collision>
            <geometry>
                <mesh filename="package://IRB120/urdf/meshes/collision/finger.stl" />
            </geometry>
        </collision>
        
        <inertial>
            <mass value="0.1" />
            <inertia ixx="0.03" iyy="0.03" izz="0.03" ixy="0.0" ixz="0.0" iyz="0.0" />
        </inertial>

    </link>
    <link name="gripper_rightfinger">
        <visual>
            <origin rpy="0 0 3.14159265359" xyz="0 0 0" />
            <geometry>
                <mesh filename="package://IRB120/urdf/meshes/visual/finger.dae" />
            </geometry>
        </visual>
        <collision>
            <origin rpy="0 0 3.14159265359" xyz="0 0 0" />
            <geometry>
                <mesh filename="package://IRB120/urdf/meshes/collision/finger.stl" />
            </geometry>
        </collision>
        
        <inertial>
            <mass value="0.1" />
            <inertia ixx="0.03" iyy="0.03" izz="0.03" ixy="0.0" ixz="0.0" iyz="0.0" />
        </inertial>

    </link>


    <joint name="joint_1" type="revolute">
        <origin rpy="0 0 0" xyz="0 0 0" />
        <parent link="base_link" />
        <child link="link_1" />
        <limit effort="50" lower="-2.87979" upper="2.87979" velocity="4.36332" />
        <axis xyz="0 0 1" />
        <dynamics damping="0.0" friction="0.0" />
    </joint>
    <joint name="joint_2" type="revolute">
        <origin rpy="0 0 0" xyz="0 0 0.29" />
        <parent link="link_1" />
        <child link="link_2" />
        <limit effort="50" lower="-1.91986" upper="1.91986" velocity="4.36332" />
        <axis xyz="0 1 0" />
        <dynamics damping="0.0" friction="0.0" />
    </joint>
    <joint name="joint_3" type="revolute">
        <origin rpy="0 0 0" xyz="0 0 0.27" />
        <parent link="link_2" />
        <child link="link_3" />
        <limit effort="50" lower="-1.91986" upper="1.22173" velocity="4.36332" />
        <axis xyz="0 1 0" />
        <dynamics damping="0.7" friction="0.2" />
    </joint>
    <joint name="joint_4" type="revolute">
        <origin rpy="0 0 0" xyz="0 0 0.07" />
        <parent link="link_3" />
        <child link="link_4" />
        <limit effort="50" lower="-2.79253" upper="2.79253" velocity="5.58505" />
        <axis xyz="1 0 0" />
        <dynamics damping="0.0" friction="0.0" />
    </joint>
    <joint name="joint_5" type="revolute">
        <origin rpy="0 0 0" xyz="0.302 0 0" />
        <parent link="link_4" />
        <child link="link_5" />
        <limit effort="50" lower="-2.094395" upper="2.094395" velocity="5.58505" />
        <axis xyz="0 1 0" />
        <dynamics damping="0.0" friction="0.0" />
    </joint>
    <joint name="joint_6" type="revolute">
        <origin rpy="0 0 0" xyz="0.072 0 0" />
        <parent link="link_5" />
        <child link="link_6" />
        <limit effort="50" lower="-6.98132" upper="6.98132" velocity="7.33038" />
        <axis xyz="1 0 0" />
        <dynamics damping="0.0" friction="0.0" />
    </joint>
    <joint name="abb_hand_joint" type="fixed">
        <parent link="link_6" />
        <child link="gripper_hand" />
        <origin rpy="0 1.570796327 0" xyz="0 0 0" />
    </joint>
    <joint name="gripper_finger_joint1" type="prismatic">
        <parent link="gripper_hand" />
        <child link="gripper_leftfinger" />
        <origin rpy="0 0 0" xyz="0 0 0.0584" />
        <axis xyz="0 1 0" />
        <limit effort="20" lower="0.0" upper="0.04" velocity="0.2" />
    </joint>
    <joint name="gripper_finger_joint2" type="prismatic">
        <parent link="gripper_hand" />
        <child link="gripper_rightfinger" />
        <origin rpy="0 0 0" xyz="0 0 0.0584" />
        <axis xyz="0 -1 0" />
        <limit effort="20" lower="0.0" upper="0.04" velocity="0.2" />
        <!-- <mimic joint="gripper_finger_joint1" /> -->
    </joint>
    <!-- end of joint list -->
    <!-- ROS base_link to ABB World Coordinates transform -->
    <link name="world"/>
    <joint name="base_link_base" type="fixed">
        <parent link="world" />
        <child link="base_link" />
    </joint>
    


    <!-- ros2_control hardware for Gazebo (Fortress) -->
    <ros2_control name="GazeboSimSystem" type="system">
    <hardware>
        <plugin>gz_ros2_control/GazeboSimSystem</plugin>
    </hardware>

    <!-- Your joints (position control) -->
    <joint name="joint_1">
        <command_interface name="position"/>
        <state_interface name="position"/>
        <state_interface name="velocity"/>
    </joint>
    <joint name="joint_2">
        <command_interface name="position"/>
        <state_interface name="position"/>
        <state_interface name="velocity"/>
    </joint>
    <joint name="joint_3">
        <command_interface name="position"/>
        <state_interface name="position"/>
        <state_interface name="velocity"/>
    </joint>
    <joint name="joint_4">
        <command_interface name="position"/>
        <state_interface name="position"/>
        <state_interface name="velocity"/>
    </joint>
    <joint name="joint_5">
        <command_interface name="position"/>
        <state_interface name="position"/>
        <state_interface name="velocity"/>
    </joint>
    <joint name="joint_6">
        <command_interface name="position"/>
        <state_interface name="position"/>
        <state_interface name="velocity"/>
    </joint>


    <!-- <joint name="abb_hand_joint">
        <command_interface name="position"/>
        <state_interface name="position"/>
        <state_interface name="velocity"/>
    </joint> -->

    <joint name="gripper_finger_joint1">
        <command_interface name="position"/>
        <state_interface name="position"/>
        <state_interface name="velocity"/>
    </joint>

    <joint name="gripper_finger_joint2">
        <command_interface name="position"/>
        <state_interface name="position"/>
        <state_interface name="velocity"/>
    </joint>

    </ros2_control>

    <!-- Load the Gazebo-Sim (Fortress) control plugin -->
    <gazebo>
        <plugin filename="gz_ros2_control-system" name="gz_ros2_control::GazeboSimROS2ControlPlugin">
        <!-- <plugin filename="ign_ros2_control-system" name="ign_ros2_control::IgnitionROS2ControlPlugin"> -->

            <!-- optional: where to read robot_description from -->
            <robot_param>robot_description</robot_param>
            <robot_param_node>robot_state_publisher</robot_param_node>
            <!-- point to your controllers YAML (see step 3) -->
            <parameters>./IRB120/config/IRB120_controller.yaml</parameters>
        </plugin>
    </gazebo>



</robot>
